<?xml version="1.0"?>
<robot name="quadcopter">

  <!-- Materials -->
  <material name="black">
    <color rgba="0.1 0.1 0.1 1.0"/>
  </material>
  
  <material name="red">
    <color rgba="0.8 0.1 0.1 1.0"/>
  </material>
  
  <material name="blue">
    <color rgba="0.1 0.1 0.8 1.0"/>
  </material>
  
  <material name="gray">
    <color rgba="0.5 0.5 0.5 1.0"/>
  </material>
  
  <material name="white">
    <color rgba="0.9 0.9 0.9 1.0"/>
  </material>

  <!-- Base link (main body) -->
  <link name="base_link">
    <visual>
      <origin xyz="0 0 0" rpy="0 0 0"/>
      <geometry>
        <box size="0.15 0.15 0.05"/>
      </geometry>
      <material name="black"/>
    </visual>
    
    <collision>
      <origin xyz="0 0 0" rpy="0 0 0"/>
      <geometry>
        <box size="0.15 0.15 0.05"/>
      </geometry>
    </collision>
    
    <inertial>
      <origin xyz="0 0 0" rpy="0 0 0"/>
      <mass value="1.0"/>
      <inertia ixx="0.015" ixy="0" ixz="0" iyy="0.015" iyz="0" izz="0.025"/>
    </inertial>
  </link>

  <!-- Front Right Arm -->
  <link name="arm_front_right">
    <visual>
      <origin xyz="0 0 0" rpy="0 0 0"/>
      <geometry>
        <box size="0.15 0.02 0.01"/>
      </geometry>
      <material name="red"/>
    </visual>
    
    <collision>
      <origin xyz="0 0 0" rpy="0 0 0"/>
      <geometry>
        <box size="0.15 0.02 0.01"/>
      </geometry>
    </collision>
    
    <inertial>
      <origin xyz="0 0 0" rpy="0 0 0"/>
      <mass value="0.05"/>
      <inertia ixx="0.0001" ixy="0" ixz="0" iyy="0.001" iyz="0" izz="0.001"/>
    </inertial>
  </link>

  <joint name="arm_front_right_joint" type="fixed">
    <origin xyz="0.075 -0.075 0" rpy="0 0 0.785398"/>
    <parent link="base_link"/>
    <child link="arm_front_right"/>
  </joint>

  <!-- Front Left Arm -->
  <link name="arm_front_left">
    <visual>
      <origin xyz="0 0 0" rpy="0 0 0"/>
      <geometry>
        <box size="0.15 0.02 0.01"/>
      </geometry>
      <material name="red"/>
    </visual>
    
    <collision>
      <origin xyz="0 0 0" rpy="0 0 0"/>
      <geometry>
        <box size="0.15 0.02 0.01"/>
      </geometry>
    </collision>
    
    <inertial>
      <origin xyz="0 0 0" rpy="0 0 0"/>
      <mass value="0.05"/>
      <inertia ixx="0.0001" ixy="0" ixz="0" iyy="0.001" iyz="0" izz="0.001"/>
    </inertial>
  </link>

  <joint name="arm_front_left_joint" type="fixed">
    <origin xyz="0.075 0.075 0" rpy="0 0 -0.785398"/>
    <parent link="base_link"/>
    <child link="arm_front_left"/>
  </joint>

  <!-- Back Right Arm -->
  <link name="arm_back_right">
    <visual>
      <origin xyz="0 0 0" rpy="0 0 0"/>
      <geometry>
        <box size="0.15 0.02 0.01"/>
      </geometry>
      <material name="blue"/>
    </visual>
    
    <collision>
      <origin xyz="0 0 0" rpy="0 0 0"/>
      <geometry>
        <box size="0.15 0.02 0.01"/>
      </geometry>
    </collision>
    
    <inertial>
      <origin xyz="0 0 0" rpy="0 0 0"/>
      <mass value="0.05"/>
      <inertia ixx="0.0001" ixy="0" ixz="0" iyy="0.001" iyz="0" izz="0.001"/>
    </inertial>
  </link>

  <joint name="arm_back_right_joint" type="fixed">
    <origin xyz="-0.075 -0.075 0" rpy="0 0 -0.785398"/>
    <parent link="base_link"/>
    <child link="arm_back_right"/>
  </joint>

  <!-- Back Left Arm -->
  <link name="arm_back_left">
    <visual>
      <origin xyz="0 0 0" rpy="0 0 0"/>
      <geometry>
        <box size="0.15 0.02 0.01"/>
      </geometry>
      <material name="blue"/>
    </visual>
    
    <collision>
      <origin xyz="0 0 0" rpy="0 0 0"/>
      <geometry>
        <box size="0.15 0.02 0.01"/>
      </geometry>
    </collision>
    
    <inertial>
      <origin xyz="0 0 0" rpy="0 0 0"/>
      <mass value="0.05"/>
      <inertia ixx="0.0001" ixy="0" ixz="0" iyy="0.001" iyz="0" izz="0.001"/>
    </inertial>
  </link>

  <joint name="arm_back_left_joint" type="fixed">
    <origin xyz="-0.075 0.075 0" rpy="0 0 0.785398"/>
    <parent link="base_link"/>
    <child link="arm_back_left"/>
  </joint>

  <!-- Motors -->
  <!-- Front Right Motor -->
  <link name="motor_front_right">
    <visual>
      <origin xyz="0 0 0" rpy="0 0 0"/>
      <geometry>
        <cylinder radius="0.015" length="0.03"/>
      </geometry>
      <material name="gray"/>
    </visual>
    
    <collision>
      <origin xyz="0 0 0" rpy="0 0 0"/>
      <geometry>
        <cylinder radius="0.015" length="0.03"/>
      </geometry>
    </collision>
    
    <inertial>
      <origin xyz="0 0 0" rpy="0 0 0"/>
      <mass value="0.02"/>
      <inertia ixx="0.00001" ixy="0" ixz="0" iyy="0.00001" iyz="0" izz="0.00001"/>
    </inertial>
  </link>

  <joint name="motor_front_right_joint" type="fixed">
    <origin xyz="0.075 0 0.02" rpy="0 0 0"/>
    <parent link="arm_front_right"/>
    <child link="motor_front_right"/>
  </joint>

  <!-- Front Left Motor -->
  <link name="motor_front_left">
    <visual>
      <origin xyz="0 0 0" rpy="0 0 0"/>
      <geometry>
        <cylinder radius="0.015" length="0.03"/>
      </geometry>
      <material name="gray"/>
    </visual>
    
    <collision>
      <origin xyz="0 0 0" rpy="0 0 0"/>
      <geometry>
        <cylinder radius="0.015" length="0.03"/>
      </geometry>
    </collision>
    
    <inertial>
      <origin xyz="0 0 0" rpy="0 0 0"/>
      <mass value="0.02"/>
      <inertia ixx="0.00001" ixy="0" ixz="0" iyy="0.00001" iyz="0" izz="0.00001"/>
    </inertial>
  </link>

  <joint name="motor_front_left_joint" type="fixed">
    <origin xyz="0.075 0 0.02" rpy="0 0 0"/>
    <parent link="arm_front_left"/>
    <child link="motor_front_left"/>
  </joint>

  <!-- Back Right Motor -->
  <link name="motor_back_right">
    <visual>
      <origin xyz="0 0 0" rpy="0 0 0"/>
      <geometry>
        <cylinder radius="0.015" length="0.03"/>
      </geometry>
      <material name="gray"/>
    </visual>
    
    <collision>
      <origin xyz="0 0 0" rpy="0 0 0"/>
      <geometry>
        <cylinder radius="0.015" length="0.03"/>
      </geometry>
    </collision>
    
    <inertial>
      <origin xyz="0 0 0" rpy="0 0 0"/>
      <mass value="0.02"/>
      <inertia ixx="0.00001" ixy="0" ixz="0" iyy="0.00001" iyz="0" izz="0.00001"/>
    </inertial>
  </link>

  <joint name="motor_back_right_joint" type="fixed">
    <origin xyz="0.075 0 0.02" rpy="0 0 0"/>
    <parent link="arm_back_right"/>
    <child link="motor_back_right"/>
  </joint>

  <!-- Back Left Motor -->
  <link name="motor_back_left">
    <visual>
      <origin xyz="0 0 0" rpy="0 0 0"/>
      <geometry>
        <cylinder radius="0.015" length="0.03"/>
      </geometry>
      <material name="gray"/>
    </visual>
    
    <collision>
      <origin xyz="0 0 0" rpy="0 0 0"/>
      <geometry>
        <cylinder radius="0.015" length="0.03"/>
      </geometry>
    </collision>
    
    <inertial>
      <origin xyz="0 0 0" rpy="0 0 0"/>
      <mass value="0.02"/>
      <inertia ixx="0.00001" ixy="0" ixz="0" iyy="0.00001" iyz="0" izz="0.00001"/>
    </inertial>
  </link>

  <joint name="motor_back_left_joint" type="fixed">
    <origin xyz="0.075 0 0.02" rpy="0 0 0"/>
    <parent link="arm_back_left"/>
    <child link="motor_back_left"/>
  </joint>

  <!-- Propellers -->
  <!-- Front Right Propeller -->
  <link name="propeller_front_right">
    <visual>
      <origin xyz="0 0 0" rpy="0 0 0"/>
      <geometry>
        <cylinder radius="0.08" length="0.005"/>
      </geometry>
      <material name="white"/>
    </visual>
    
    <collision>
      <origin xyz="0 0 0" rpy="0 0 0"/>
      <geometry>
        <cylinder radius="0.08" length="0.005"/>
      </geometry>
    </collision>
    
    <inertial>
      <origin xyz="0 0 0" rpy="0 0 0"/>
      <mass value="0.01"/>
      <inertia ixx="0.00001" ixy="0" ixz="0" iyy="0.00001" iyz="0" izz="0.00002"/>
    </inertial>
  </link>

  <joint name="propeller_front_right_joint" type="continuous">
    <origin xyz="0 0 0.02" rpy="0 0 0"/>
    <parent link="motor_front_right"/>
    <child link="propeller_front_right"/>
    <axis xyz="0 0 1"/>
  </joint>

  <!-- Front Left Propeller -->
  <link name="propeller_front_left">
    <visual>
      <origin xyz="0 0 0" rpy="0 0 0"/>
      <geometry>
        <cylinder radius="0.08" length="0.005"/>
      </geometry>
      <material name="white"/>
    </visual>
    
    <collision>
      <origin xyz="0 0 0" rpy="0 0 0"/>
      <geometry>
        <cylinder radius="0.08" length="0.005"/>
      </geometry>
    </collision>
    
    <inertial>
      <origin xyz="0 0 0" rpy="0 0 0"/>
      <mass value="0.01"/>
      <inertia ixx="0.00001" ixy="0" ixz="0" iyy="0.00001" iyz="0" izz="0.00002"/>
    </inertial>
  </link>

  <joint name="propeller_front_left_joint" type="continuous">
    <origin xyz="0 0 0.02" rpy="0 0 0"/>
    <parent link="motor_front_left"/>
    <child link="propeller_front_left"/>
    <axis xyz="0 0 1"/>
  </joint>

  <!-- Back Right Propeller -->
  <link name="propeller_back_right">
    <visual>
      <origin xyz="0 0 0" rpy="0 0 0"/>
      <geometry>
        <cylinder radius="0.08" length="0.005"/>
      </geometry>
      <material name="white"/>
    </visual>
    
    <collision>
      <origin xyz="0 0 0" rpy="0 0 0"/>
      <geometry>
        <cylinder radius="0.08" length="0.005"/>
      </geometry>
    </collision>
    
    <inertial>
      <origin xyz="0 0 0" rpy="0 0 0"/>
      <mass value="0.01"/>
      <inertia ixx="0.00001" ixy="0" ixz="0" iyy="0.00001" iyz="0" izz="0.00002"/>
    </inertial>
  </link>

  <joint name="propeller_back_right_joint" type="continuous">
    <origin xyz="0 0 0.02" rpy="0 0 0"/>
    <parent link="motor_back_right"/>
    <child link="propeller_back_right"/>
    <axis xyz="0 0 1"/>
  </joint>

  <!-- Back Left Propeller -->
  <link name="propeller_back_left">
    <visual>
      <origin xyz="0 0 0" rpy="0 0 0"/>
      <geometry>
        <cylinder radius="0.08" length="0.005"/>
      </geometry>
      <material name="white"/>
    </visual>
    
    <collision>
      <origin xyz="0 0 0" rpy="0 0 0"/>
      <geometry>
        <cylinder radius="0.08" length="0.005"/>
      </geometry>
    </collision>
    
    <inertial>
      <origin xyz="0 0 0" rpy="0 0 0"/>
      <mass value="0.01"/>
      <inertia ixx="0.00001" ixy="0" ixz="0" iyy="0.00001" iyz="0" izz="0.00002"/>
    </inertial>
  </link>

  <joint name="propeller_back_left_joint" type="continuous">
    <origin xyz="0 0 0.02" rpy="0 0 0"/>
    <parent link="motor_back_left"/>
    <child link="propeller_back_left"/>
    <axis xyz="0 0 1"/>
  </joint>

</robot>